Workbook

Sheet 📊 Dashboard
B2: 🇮🇳 Indian Founder Personal Finance Planner
B3: Update your inputs on the '⚙️ Inputs' sheet — all numbers here update automatically
B6: 📋 FINANCIAL HEALTH SCORECARD
B7: Metric | C7: Value | D7: Status | E7: Benchmark
B8: Monthly Take-home (₹) | C8: ='⚙️ Inputs'!C7 -> 80000 | D8: —
B9: Monthly Burn (₹) | C9: ='⚙️ Inputs'!C14 -> 8000 | D9: —
B10: Monthly Surplus / Deficit | C10: ='⚙️ Inputs'!C7-'⚙️ Inputs'!C14 -> 72000 | D10: =IF('⚙️ Inputs'!C7-'⚙️ Inputs'!C14>=0,"✅ Surplus","🔴 Deficit") -> ✅ Surplus
B11: Savings Rate | C11: =IF('⚙️ Inputs'!C7>0,('⚙️ Inputs'!C7-'⚙️ Inputs'!C14)/'⚙️ Inputs'!C7,0) -> 0.9 | D11: =IF(IF('⚙️ Inputs'!C7>0,('⚙️ Inputs'!C7-'⚙️ Inputs'!C14)/'⚙️ Inputs'!C7,0)>=0,"✅ ≥20%","🔴 <10%") -> ✅ ≥20% | E11: ≥20%
B12: Emergency Fund (months) | C12: =IF('⚙️ Inputs'!C14>0,'⚙️ Inputs'!C20/'⚙️ Inputs'!C14,0) -> 6.25 | D12: =IF(IF('⚙️ Inputs'!C14>0,'⚙️ Inputs'!C20/'⚙️ Inputs'!C14,0)>=0,"✅ ≥6 mo","🔴 <3 mo") -> ✅ ≥6 mo | E12: ≥6 mo
B13: Personal Runway (months) | C13: =IF(('⚙️ Inputs'!C14-'⚙️ Inputs'!C7)>0,'⚙️ Inputs'!C20/('⚙️ Inputs'!C14-'⚙️ Inputs'!C7),99) -> 99 | D13: =IF(IF(('⚙️ Inputs'!C14-'⚙️ Inputs'!C7)>0,'⚙️ Inputs'!C20/('⚙️ Inputs'!C14-'⚙️ Inputs'!C7),99)>=0,"✅ ≥12 mo","🔴 <6 mo") -> ✅ ≥12 mo | E13: ≥12 mo
B14: EMI-to-Income Ratio | C14: =IF('⚙️ Inputs'!C7>0,'⚙️ Inputs'!C17/'⚙️ Inputs'!C7,0) -> 0 | D14: =IF(IF('⚙️ Inputs'!C7>0,'⚙️ Inputs'!C17/'⚙️ Inputs'!C7,0)>=0,"✅ <25%","🔴 >40%") -> ✅ <25% | E14: <25%
B15: Annual Tax Saving Available | C15: ='💸 Tax Planner'!C38 -> 15 September 2025 | D15: —
B18: 💼 YOUR INVESTMENT STACK STATUS
B19: Layer | C19: Instrument | D19: Target/yr | E19: Invested/yr | F19: Gap
B20: 🔴 Survival | C20: Emergency Fund (6× burn) | D20: ='⚙️ Inputs'!C14*6 -> 48000 | E20: ='⚙️ Inputs'!C20 -> 50000 | F20: =D20-E20 -> -2000
B21: 🟡 Tax Shield | C21: PPF (Section 80C) | D21: =150000 -> 150000 | E21: ='💼 Investments'!C8 -> 0 | F21: =D21-E21 -> 150000
B22: 🟡 Tax Shield | C22: NPS Tier 1 (80CCD 1B) | D22: =50000 -> 50000 | E22: ='💼 Investments'!C9 -> 0 | F22: =D22-E22 -> 50000
B23: 🟡 Tax Shield | C23: Health Ins Premium (80D) | D23: =25000 -> 25000 | E23: ='⚙️ Inputs'!C32 -> 0 | F23: =D23-E23 -> 25000
B24: 🟢 Wealth | C24: Index Fund SIP (Nifty 50) | D24: ='💼 Investments'!C12*12 -> 0 | E24: ='💼 Investments'!C12*12 -> 0 | F24: =0 -> 0
B25: 🟢 Wealth | C25: Flexicap SIP | D25: ='💼 Investments'!C13*12 -> 0 | E25: ='💼 Investments'!C13*12 -> 0 | F25: =0 -> 0
B27: ⚡ QUICK ACTION ALERTS
B28: 🔴 Emergency fund < 3 months → Top priority before any investing
B29: 🟡 PPF not maxed → Fill ₹1.5L before 5 April every year for EEE benefit
B30: 🟡 NPS 80CCD(1B) unused → ₹50,000 saves ₹15,600 in tax (30% bracket)
B31: 🔴 No personal health insurance → Buy before a medical event, not after
B32: 🟡 Advance tax due → 15 Jun / 15 Sep / 15 Dec / 15 Mar (see Tax sheet)

Sheet ⚙️ Inputs
B2: ⚙️ Your Profile & Inputs [Edit BLUE cells only]
B3: Blue cells = your inputs | Yellow background = key inputs | All other sheets update automatically
B5: 👤 PERSONAL PROFILE
B6: Your Name | C6: Founder Name
B7: Monthly Take-home (₹) | C7: 80000
B8: Age (years) | C8: 30
B9: City | C9: Bengaluru
B10: Dependents | C10: Spouse, 1 child
B12: 🏠 MONTHLY EXPENSES (₹)
B13: Rent / Home Loan EMI | C13: 25000
B14: Food & Groceries | C14: 8000
B15: Transport | C15: 4000
B16: Subscriptions & Tools | C16: 3000
B17: Other EMIs (loans etc.) | C17: 0
B18: Family / Parent Support | C18: 5000
B19: Miscellaneous | C19: 5000
B20: Total Monthly Burn (₹) | C20: =SUM(C13:C19) -> 50000
B22: 💰 SAVINGS & EXISTING INVESTMENTS (₹)
B23: Cash in Savings Account | C23: 200000
B24: Fixed Deposits (FDs) | C24: 50000
B25: Liquid Mutual Funds | C25: 0
B26: Total Liquid Savings | C26: =SUM(C23:C25) -> 250000
B27: PPF Balance | C27: 80000
B28: NPS Balance | C28: 0
B29: Mutual Fund Portfolio | C29: 50000
B30: EPF (from prior job) | C30: 0
B31: Total Investments (ex-equity) | C31: =SUM(C27:C30) -> 130000
B33: 🛡️ INSURANCE
B34: Health Insurance Cover (₹) | C34: 0
B35: Term Life Cover (₹) | C35: 0
B36: Health Premium Paid/yr (₹) | C36: 0
B38: 🚀 STARTUP & EQUITY
B39: Startup Stage | C39: Bootstrapped
B40: Your Equity Stake (%) | C40: 0.5
B41: ESOPs Granted (shares) | C41: 0
B42: ESOP Strike Price (₹) | C42: 0
B43: ESOP FMV Today (₹) | C43: 0
B45: 🧾 TAX DETAILS
B46: Tax Regime | C46: Old
B47: HRA Received / yr (₹) | C47: 0
...

Sheet 💵 Cash Flow
B2: 💵 Monthly Cash Flow Planner (12-Month View)
B4: Category | C4: Apr | D4: May | E4: Jun | F4: Jul | G4: Aug | H4: Sep | I4: Oct | J4: Nov | K4: Dec | L4: Jan | M4: Feb | N4: Mar
B5: INCOME
B6: Take-home Salary | C6: ='⚙️ Inputs'!C7 -> 80000 | D6: ='⚙️ Inputs'!C7 -> 80000 | E6: ='⚙️ Inputs'!C7 -> 80000 | F6: ='⚙️ Inputs'!C7 -> 80000 | G6: ='⚙️ Inputs'!C7 -> 80000 | H6: ='⚙️ Inputs'!C7 -> 80000 | I6: ='⚙️ Inputs'!C7 -> 80000 | J6: ='⚙️ Inputs'!C7 -> 80000 | K6: ='⚙️ Inputs'!C7 -> 80000 | L6: ='⚙️ Inputs'!C7 -> 80000 | M6: ='⚙️ Inputs'!C7 -> 80000 | N6: ='⚙️ Inputs'!C7 -> 80000
B7: Other Income | C7: 0 | D7: 0 | E7: 0 | F7: 0 | G7: 0 | H7: 0 | I7: 0 | J7: 0 | K7: 0 | L7: 0 | M7: 0 | N7: 0
B8: Total Income | C8: =SUM(C6:C7) -> 80000 | D8: =SUM(D6:D7) -> 80000 | E8: =SUM(E6:E7) -> 80000 | F8: =SUM(F6:F7) -> 80000 | G8: =SUM(G6:G7) -> 80000 | H8: =SUM(H6:H7) -> 80000 | I8: =SUM(I6:I7) -> 80000 | J8: =SUM(J6:J7) -> 80000 | ... N8: =SUM(N6:N7) -> 80000
B10: EXPENSES
B11: Rent / Home EMI | C11: ='⚙️ Inputs'!C13 -> 25000 | D11: ='⚙️ Inputs'!C13 -> 25000 | E11: ='⚙️ Inputs'!C13 -> 25000 | F11: ='⚙️ Inputs'!C13 -> 25000 | G11: ='⚙️ Inputs'!C13 -> 25000 | H11: ='⚙️ Inputs'!C13 -> 25000 | I11: ='⚙️ Inputs'!C13 -> 25000 | J11: ='⚙️ Inputs'!C13 -> 25000 | K11: ='⚙️ Inputs'!C13 -> 25000 | L11: ='⚙️ Inputs'!C13 -> 25000 | M11: ='⚙️ Inputs'!C13 -> 25000 | N11: ='⚙️ Inputs'!C13 -> 25000
B12: Food & Groceries | C12: ='⚙️ Inputs'!C14 -> 8000 | D12: ='⚙️ Inputs'!C14 -> 8000 | E12: ='⚙️ Inputs'!C14 -> 8000 | F12: ='⚙️ Inputs'!C14 -> 8000 | G12: ='⚙️ Inputs'!C14 -> 8000 | H12: ='⚙️ Inputs'!C14 -> 8000 | I12: ='⚙️ Inputs'!C14 -> 8000 | J12: ='⚙️ Inputs'!C14 -> 8000 | K12: ='⚙️ Inputs'!C14 -> 8000 | L12: ='⚙️ Inputs'!C14 -> 8000 | M12: ='⚙️ Inputs'!C14 -> 8000 | N12: ='⚙️ Inputs'!C14 -> 8000
B13: Transport | C13: ='⚙️ Inputs'!C15 -> 4000 | D13: ='⚙️ Inputs'!C15 -> 4000 | E13: ='⚙️ Inputs'!C15 -> 4000 | F13: ='⚙️ Inputs'!C15 -> 4000 | G13: ='⚙️ Inputs'!C15 -> 4000 | H13: ='⚙️ Inputs'!C15 -> 4000 | I13: ='⚙️ Inputs'!C15 -> 4000 | J13: ='⚙️ Inputs'!C15 -> 4000 | K13: ='⚙️ Inputs'!C15 -> 4000 | L13: ='⚙️ Inputs'!C15 -> 4000 | M13: ='⚙️ Inputs'!C15 -> 4000 | N13: ='⚙️ Inputs'!C15 -> 4000
B14: Subscriptions | C14: ='⚙️ Inputs'!C16 -> 3000 | D14: ='⚙️ Inputs'!C16 -> 3000 | E14: ='⚙️ Inputs'!C16 -> 3000 | F14: ='⚙️ Inputs'!C16 -> 3000 | G14: ='⚙️ Inputs'!C16 -> 3000 | H14: ='⚙️ Inputs'!C16 -> 3000 | I14: ='⚙️ Inputs'!C16 -> 3000 | J14: ='⚙️ Inputs'!C16 -> 3000 | K14: ='⚙️ Inputs'!C16 -> 3000 | L14: ='⚙️ Inputs'!C16 -> 3000 | M14: ='⚙️ Inputs'!C16 -> 3000 | N14: ='⚙️ Inputs'!C16 -> 3000
B15: Other EMIs | C15: ='⚙️ Inputs'!C17 -> 0 | D15: ='⚙️ Inputs'!C17 -> 0 | E15: ='⚙️ Inputs'!C17 -> 0 | F15: ='⚙️ Inputs'!C17 -> 0 | G15: ='⚙️ Inputs'!C17 -> 0 | H15: ='⚙️ Inputs'!C17 -> 0 | I15: ='⚙️ Inputs'!C17 -> 0 | J15: ='⚙️ Inputs'!C17 -> 0 | K15: ='⚙️ Inputs'!C17 -> 0 | L15: ='⚙️ Inputs'!C17 -> 0 | M15: ='⚙️ Inputs'!C17 -> 0 | N15: ='⚙️ Inputs'!C17 -> 0
B16: Family Support | C16: ='⚙️ Inputs'!C18 -> 5000 | D16: ='⚙️ Inputs'!C18 -> 5000 | E16: ='⚙️ Inputs'!C18 -> 5000 | F16: ='⚙️ Inputs'!C18 -> 5000 | G16: ='⚙️ Inputs'!C18 -> 5000 | H16: ='⚙️ Inputs'!C18 -> 5000 | I16: ='⚙️ Inputs'!C18 -> 5000 | J16: ='⚙️ Inputs'!C18 -> 5000 | K16: ='⚙️ Inputs'!C18 -> 5000 | L16: ='⚙️ Inputs'!C18 -> 5000 | M16: ='⚙️ Inputs'!C18 -> 5000 | N16: ='⚙️ Inputs'!C18 -> 5000
B17: Miscellaneous | C17: ='⚙️ Inputs'!C19 -> 5000 | D17: ='⚙️ Inputs'!C19 -> 5000 | E17: ='⚙️ Inputs'!C19 -> 5000 | F17: ='⚙️ Inputs'!C19 -> 5000 | G17: ='⚙️ Inputs'!C19 -> 5000 | H17: ='⚙️ Inputs'!C19 -> 5000 | I17: ='⚙️ Inputs'!C19 -> 5000 | J17: ='⚙️ Inputs'!C19 -> 5000 | K17: ='⚙️ Inputs'!C19 -> 5000 | L17: ='⚙️ Inputs'!C19 -> 5000 | M17: ='⚙️ Inputs'!C19 -> 5000 | N17: ='⚙️ Inputs'!C19 -> 5000
B18: Total Expenses | C18: =SUM(C11:C17) -> 50000 | D18: =SUM(D11:D17) -> 50000 | E18: =SUM(E11:E17) -> 50000 | F18: =SUM(F11:F17) -> 50000 | G18: =SUM(G11:G17) -> 50000 | H18: =SUM(H11:H17) -> 50000 | I18: =SUM(I11:I17) -> 50000 | J18: =SUM(J11:J17) -> 50000 | ... N18: =SUM(N11:N17) -> 50000
B20: NET SURPLUS / (DEFICIT) | C20: =C8-C18 -> 30000 | D20: =D8-D18 -> 30000 | E20: =E8-E18 -> 30000 | F20: =F8-F18 -> 30000 | G20: =G8-G18 -> 30000 | H20: =H8-H18 -> 30000 | I20: =I8-I18 -> 30000 | J20: =J8-J18 -> 30000 | ... N20: =N8-N18 -> 30000
B21: Cumulative Cash Position | C21: ='⚙️ Inputs'!C26+C20 -> 280000 | D21: =C21+D20 -> 310000 | E21: =D21+E20 -> 340000 | F21: =E21+F20 -> 370000 | G21: =F21+G20 -> 400000 | H21: =G21+H20 -> 430000 | I21: =H21+I20 -> 460000 | J21: =I21+J20 -> 490000 | K21: =J21+K20 -> 520000 | ... N21: =M21+N20 -> 610000
B23: 📊 KEY METRICS
B24: Personal Runway (months) | C24: =IF(('⚙️ Inputs'!C20-'⚙️ Inputs'!C7)>0,'⚙️ Inputs'!C26/('⚙️ Inputs'!C20-'⚙️ Inputs'!C7),99) -> 99
B25: Monthly Savings Rate | C25: =IF('⚙️ Inputs'!C7>0,('⚙️ Inputs'!C7-'⚙️ Inputs'!C20)/'⚙️ Inputs'!C7,0) -> 0.375
B26: Emergency Fund Target (₹) | C26: ='⚙️ Inputs'!C20*6 -> 300000
B27: Emergency Fund Current (₹) | C27: ='⚙️ Inputs'!C26 -> 250000
B28: Emergency Fund Gap (₹) | C28: =C26-C27 -> 50000
B29: EMI-to-Income Ratio | C29: =IF('⚙️ Inputs'!C7>0,'⚙️ Inputs'!C17/'⚙️ Inputs'!C7,0) -> 0

Sheet 💸 Tax Planner
B2: 💸 Tax Planner — Old vs New Regime Comparison (FY 2024-25)
B4: Component | C4: Old Regime | D4: New Regime | E4: Difference (Old-New)
B5: Gross Annual Income (Salary) | C5: ='⚙️ Inputs'!C7*12 -> 960000 | D5: ='⚙️ Inputs'!C7*12 -> 960000 | E5: =C5-D5 -> 0
B7: DEDUCTIONS (Old Regime Only)
B8: Standard Deduction (Sec 16) | C8: =50000 -> 50000 | D8: —
B9: HRA Exemption | C9: ='⚙️ Inputs'!C47 -> 0 | D9: —
B10: 80C: PPF + ELSS + LIC + EPF | C10: =MIN('💼 Investments'!C8+'💼 Investments'!C9,150000) -> 0 | D10: —
B11: 80CCD(1B): NPS Tier 1 | C11: =MIN('💼 Investments'!C10,50000) -> 0 | D11: —
B12: 80D: Health Ins Premium | C12: =MIN('⚙️ Inputs'!C36,25000) -> 0 | D12: —
B13: Home Loan Interest (Sec 24b) | C13: =MIN('⚙️ Inputs'!C48,200000) -> 0 | D13: —
B14: LTA | C14: ='⚙️ Inputs'!C49 -> 0 | D14: —
B15: Total Deductions (Old Regime) | C15: =SUM(C8:C14) -> 50000 | D15: 75000
B17: Taxable Income | C17: =MAX(C5-C15,0) -> 910000 | D17: =MAX(C5-75000,0) -> 885000 | E17: =C17-D17 -> 25000
B19: TAX CALCULATION (FY 2024-25 Slabs)
B20: Income Tax (before cess) | C20: =MAX(0,IF(C17<=250000,0,IF(C17<=500000,(C17-250000)*0.05,IF(C17<=1000000,12500+(C17-500000)*0.2,112500+(C17-1000000)*0.3)))) -> 94500 | D20: =MAX(0,IF(D17<=300000,0,IF(D17<=700000,(D17-300000)*0.05,IF(D17<=1000000,20000+(D17-700000)*0.1,IF(D17<=1200000,50000+(D17-1000000)*0.15,IF(D17<=1500000,80000+(D17-1200000)*0.2,140000+(D17-1500000)*0.3)))))) -> 38500 | E20: =C20-D20 -> 56000
B21: Rebate u/s 87A | C21: =IF(C17<=500000,MIN(C20,12500),0) -> 0 | D21: =IF(D17<=700000,MIN(D20,25000),0) -> 0 | E21: =C21-D21 -> 0
B22: Health & Education Cess (4%) | C22: =(C20-C21)*0.04 -> 3780 | D22: =(D20-D21)*0.04 -> 1540 | E22: =C22-D22 -> 2240
B24: TOTAL TAX PAYABLE | C24: =(C20-C21)+C22 -> 98280 | D24: =(D20-D21)+D22 -> 40040 | E24: =C24-D24 -> 58240
B26: =IF(C24<D24,"✅ VERDICT: Old Regime saves ₹"&TEXT(D24-C24,"#,##0")&" vs New Regime → Stick with OLD","✅ VERDICT: New Regime saves ₹"&TEXT(C24-D24,"#,##0")&" vs Old Regime → Switch to NEW") -> ✅ VERDICT: New Regime saves ₹58,240 vs Old Regime → Switch to NEW
B28: 💡 UNUSED TAX-SAVING OPPORTUNITIES
B29: NPS 80CCD(1B) unused room | C29: =MAX(0,50000-MIN('💼 Investments'!C10,50000)) -> 50000
B30: 80C unused room | C30: =MAX(0,150000-MIN('💼 Investments'!C8+'💼 Investments'!C9,150000)) -> 150000
B31: 80D unused room (self) | C31: =MAX(0,25000-MIN('⚙️ Inputs'!C36,25000)) -> 25000
B32: Total potential tax saving | C32: =SUM(C29:C31)*0.3 -> 67500
B35: 📅 ADVANCE TAX CALENDAR (Mark in your diary!)
B36: Instalment | C36: Due Date | D36: % of Annual Tax | E36: Estimated Amount
B37: 1st Instalment | C37: 15 June 2025 | D37: 15% | E37: =C24*0.15 -> 14742
B38: 2nd Instalment | C38: 15 September 2025 | D38: 45% | E38: =C24*0.45 -> 44226
B39: 3rd Instalment | C39: 15 December 2025 | D39: 75% | E39: =C24*0.75 -> 73710
B40: 4th Instalment | C40: 15 March 2026 | D40: 100% | E40: =C24*1 -> 98280

Sheet 💼 Investments
B2: 💼 Investment Tracker & Planner
B4: Instrument | C4: Monthly SIP / Contrib | D4: Annual Amount | E4: Current Balance | F4: Target / Year
B5: 🔴 LAYER 1 — SURVIVAL (Emergency Fund)
B6: Liquid Mutual Fund (Emergency) | C6: 0 | D6: =C6*12 -> 0 | E6: ='⚙️ Inputs'!C25 -> 0 | F6: ='⚙️ Inputs'!C20*6 -> 300000
B7: 🟡 LAYER 2 — TAX SHIELD
B8: PPF (Section 80C) | C8: 0 | D8: =C8*12 -> 0 | E8: ='⚙️ Inputs'!C27 -> 80000 | F8: 150000
B9: NPS Tier 1 (80CCD 1B) | C9: 0 | D9: =C9*12 -> 0 | E9: ='⚙️ Inputs'!C28 -> 0 | F9: 50000
B10: ELSS SIP (80C remainder) | C10: 0 | D10: =C10*12 -> 0 | E10: 0 | F10: 0
B11: Health Insurance Premium | C11: 0 | D11: =C11*12 -> 0 | E11: ='⚙️ Inputs'!C36 -> 0 | F11: 25000
B12: 🟢 LAYER 3 — WEALTH BUILDING
B13: Nifty 50 Index Fund SIP | C13: 0 | D13: =C13*12 -> 0 | E13: 0 | F13: Direct plan | UTI / Nippon | 0.1% expense
B14: Flexicap Fund SIP | C14: 0 | D14: =C14*12 -> 0 | E14: 0 | F14: Direct plan | Parag Parikh | 0.6% expense
B15: NPS Tier 2 (no lock-in) | C15: 0 | D15: =C15*12 -> 0 | E15: 0 | F15: Flexible; equity + debt mix
B17: Total Monthly Investment | C17: =SUM(C6:C15) -> 0 | D17: =SUM(D6:D15) -> 0
B19: 📈 SIP COMPOUNDING PROJECTION
B20: Year | C20: Monthly SIP | D20: CAGR Assumed | E20: Corpus (Conservative 10%) | F20: Corpus (Optimistic 13%)
B21: Year 1 | C21: =C17 -> 0 | D21: 10% | E21: =C21*(((1+10%/12)^12-1)/(10%/12)) -> 0 | F21: =C21*(((1+13%/12)^12-1)/(13%/12)) -> 0
B22: Year 2 | C22: =C17 -> 0 | D22: 10% | E22: =C22*(((1+10%/12)^24-1)/(10%/12)) -> 0 | F22: =C22*(((1+13%/12)^24-1)/(13%/12)) -> 0
B23: Year 3 | C23: =C17 -> 0 | D23: 10% | E23: =C23*(((1+10%/12)^36-1)/(10%/12)) -> 0 | F23: =C23*(((1+13%/12)^36-1)/(13%/12)) -> 0
B24: Year 4 | C24: =C17 -> 0 | D24: 10% | E24: =C24*(((1+10%/12)^48-1)/(10%/12)) -> 0 | F24: =C24*(((1+13%/12)^48-1)/(13%/12)) -> 0
B25: Year 5 | C25: =C17 -> 0 | D25: 10% | E25: =C25*(((1+10%/12)^60-1)/(10%/12)) -> 0 | F25: =C25*(((1+13%/12)^60-1)/(13%/12)) -> 0
B26: Year 6 | C26: =C17 -> 0 | D26: 10% | E26: =C26*(((1+10%/12)^72-1)/(10%/12)) -> 0 | F26: =C26*(((1+13%/12)^72-1)/(13%/12)) -> 0
B27: Year 7 | C27: =C17 -> 0 | D27: 10% | E27: =C27*(((1+10%/12)^84-1)/(10%/12)) -> 0 | F27: =C27*(((1+13%/12)^84-1)/(13%/12)) -> 0
B28: Year 8 | C28: =C17 -> 0 | D28: 10% | E28: =C28*(((1+10%/12)^96-1)/(10%/12)) -> 0 | F28: =C28*(((1+13%/12)^96-1)/(13%/12)) -> 0
B29: Year 9 | C29: =C17 -> 0 | D29: 10% | E29: =C29*(((1+10%/12)^108-1)/(10%/12)) -> 0 | F29: =C29*(((1+13%/12)^108-1)/(13%/12)) -> 0
B30: Year 10 | C30: =C17 -> 0 | D30: 10% | E30: =C30*(((1+10%/12)^120-1)/(10%/12)) -> 0 | F30: =C30*(((1+13%/12)^120-1)/(13%/12)) -> 0

Sheet 🏦 Retirement
B2: 🏦 Retirement Corpus Planner
B4: ⚙️ RETIREMENT ASSUMPTIONS
B5: Current Age | C5: ='⚙️ Inputs'!C8 -> 30
B6: Target Retirement Age | C6: 60
B7: Years to Retirement | C7: =C6-C5 -> 30
B8: Current Monthly Expenses (₹) | C8: ='⚙️ Inputs'!C20 -> 50000
B9: Inflation Rate (p.a.) | C9: 0.06
B10: Expected Investment Return | C10: 0.12
B11: Safe Withdrawal Rate | C11: 0.04
B13: 📊 CORPUS REQUIREMENTS
B14: Monthly Expense at Retirement (inflation-adj) | C14: =C8*(1+C9)^C7 -> 287174.56
B15: Annual Expense at Retirement | C15: =C14*12 -> 3446094.7
B16: Required Corpus (25× Rule) | C16: =C15/C10 -> 28717456
B18: 💰 CURRENT TRAJECTORY
B19: Existing Corpus (all investments today) | C19: ='⚙️ Inputs'!C31 -> 130000
B20: FV of Existing Corpus at Retirement (12%) | C20: =C19*(1+C11)^C7 -> 421641.68
B21: Additional Corpus Needed | C21: =MAX(0,C16-C20) -> 28295814
B22: Monthly SIP Needed to Fill Gap | C22: =IF(C7>0,C21*(C11/12)/((1+C11/12)^(C7*12)-1),0) -> 40769.164
B23: You are currently investing (monthly) | C23: ='💼 Investments'!C17 -> 0
B24: Monthly Investment Gap | C24: =MAX(0,C22-C23) -> 40769.164
B26: 🗓️ CORPUS MILESTONE PROJECTIONS
B27: Age | C27: Projected Corpus (at current SIP, 12%) | D27: Target by That Age
B28: =C5+5 -> 35 | C28: =C19*(1+C11)^5+C23*(((1+C11/12)^60-1)/(C11/12)) -> 158164.88 | D28: =C8*(1+C9)^5*12*25/C10 -> 1.672782e+08
B29: =C5+10 -> 40 | C29: =C19*(1+C11)^10+C23*(((1+C11/12)^120-1)/(C11/12)) -> 192431.76 | D29: =C8*(1+C9)^10*12*25/C10 -> 2.2385596e+08
B30: =C5+15 -> 45 | C30: =C19*(1+C11)^15+C23*(((1+C11/12)^180-1)/(C11/12)) -> 234122.66 | D30: =C8*(1+C9)^15*12*25/C10 -> 2.9956977e+08
B31: =C5+20 -> 50 | C31: =C19*(1+C11)^20+C23*(((1+C11/12)^240-1)/(C11/12)) -> 284846.01 | D31: =C8*(1+C9)^20*12*25/C10 -> 4.0089193e+08
B32: =C5+25 -> 55 | C32: =C19*(1+C11)^25+C23*(((1+C11/12)^300-1)/(C11/12)) -> 346558.72 | D32: =C8*(1+C9)^25*12*25/C10 -> 5.3648384e+08

Sheet 📊 ESOP Planner
B2: 📊 ESOP & Equity Exit Planner (Unlisted Company)
B4: ⚙️ YOUR ESOP DETAILS
B5: ESOPs Granted (shares) | C5: ='⚙️ Inputs'!C41 -> 0
B6: Strike / Exercise Price (₹) | C6: ='⚙️ Inputs'!C42 -> 0
B7: FMV per Share Today (₹) | C7: ='⚙️ Inputs'!C43 -> 0
B8: Your Tax Slab (%) | C8: 0.3
B9: Holding Period after Exercise (months) | C9: 24
B11: 🧾 TAX AT EXERCISE (Perquisite Tax)
B12: Perquisite Value per Share (FMV − Strike) | C12: =MAX(0,C7-C6) -> 0
B13: Total Perquisite (all shares) | C13: =C12*C5 -> 0
B14: Tax at Exercise (at your slab rate) | C14: =C13*C8 -> 0
B15: Net Value after Exercise Tax | C15: =C13-C14 -> 0
B17: 🚀 EXIT SCENARIO MODELLER
B18: Company Exit Valuation | C18: Your Stake (from Inputs) | D18: Pre-tax Value | E18: Tax (LTCG 20% unlisted) | F18: Net Proceeds
B19: 5000000 | C19: ='⚙️ Inputs'!C40 -> 0.5 | D19: =B19*C19 -> 2500000 | E19: =D19*0.2 -> 500000 | F19: =D19-E19 -> 2000000
B20: 25000000 | C20: ='⚙️ Inputs'!C40 -> 0.5 | D20: =B20*C20 -> 12500000 | E20: =D20*0.2 -> 2500000 | F20: =D20-E20 -> 10000000
B21: 100000000 | C21: ='⚙️ Inputs'!C40 -> 0.5 | D21: =B21*C21 -> 50000000 | E21: =D21*0.2 -> 10000000 | F21: =D21-E21 -> 40000000
B22: 500000000 | C22: ='⚙️ Inputs'!C40 -> 0.5 | D22: =B22*C22 -> 250000000 | E22: =D22*0.2 -> 50000000 | F22: =D22-E22 -> 200000000
B23: 1000000000 | C23: ='⚙️ Inputs'!C40 -> 0.5 | D23: =B23*C23 -> 500000000 | E23: =D23*0.2 -> 100000000 | F23: =D23-E23 -> 400000000
B24: 0 | C24: ='⚙️ Inputs'!C40 -> 0.5 | D24: =B24*C24 -> 0 | E24: =D24*0.2 -> 0 | F24: =D24-E24 -> 0
B26: ⚠️ Note: LTCG on unlisted shares = 20% with indexation (held ≥24 months). STCG = slab rate (held <24 months). Exercise timing significantly affects tax. Consult your CA.

Sheet 🛡️ Insurance Audit
B2: 🛡️ Insurance Coverage Audit
B4: Insurance Type | C4: Required Cover | D4: You Have | E4: Gap | F4: Action Required
B5: Health Insurance | C5: =IF('⚙️ Inputs'!C9="Bengaluru",1500000,IF('⚙️ Inputs'!C9="Mumbai",2000000,1000000)) -> 1500000 | D5: ='⚙️ Inputs'!C34 -> 0 | E5: =MAX(0,C5-D5) -> 1500000 | F5: =IF(D5=0,"🔴 BUY NOW — Niva Bupa / Care Health",IF(D5<C5,"🟡 Increase cover","✅ OK")) -> 🔴 BUY NOW — Niva Bupa / Care Health
B6: Term Life Insurance | C6: =MAX(10000000,'⚙️ Inputs'!C7*12*15) -> 14400000 | D6: ='⚙️ Inputs'!C35 -> 0 | E6: =MAX(0,C6-D6) -> 14400000 | F6: =IF(D6=0,"🔴 BUY NOW — HDFC Click 2 Protect",IF(D6<C6,"🟡 Increase cover","✅ OK")) -> 🔴 BUY NOW — HDFC Click 2 Protect
B7: Personal Accident | C7: 5000000 | D7: 0 | E7: =MAX(0,C7-D7) -> 5000000 | F7: =IF(D7=0,"🟡 Consider buying — ~₹3,000/yr","✅ OK") -> 🟡 Consider buying — ~₹3,000/yr
B8: Critical Illness | C8: 2500000 | D8: 0 | E8: =MAX(0,C8-D8) -> 2500000 | F8: =IF(D8=0,"🟡 Consider if 35+ or family history","✅ OK") -> 🟡 Consider if 35+ or family history
B10: 💰 PREMIUM BENCHMARKS (Annual, Online Direct Purchase)
B11: Policy Type | C11: Cover Amount | D11: Age Band | E11: Approx Annual Premium | F11: 80D Deductible
B12: Health Floater | C12: ₹10 Lakh | D12: 30–35 | E12: ₹12,000–18,000 | F12: Yes (₹25,000 self)
B13: Health Floater | C13: ₹20 Lakh | D13: 30–35 | E13: ₹18,000–28,000 | F13: Yes (₹25,000 self)
B14: Term Life | C14: ₹1 Crore | D14: 28–32 | E14: ₹8,000–12,000 | F14: Yes (u/s 80C)
B15: Term Life | C15: ₹2 Crore | D15: 28–32 | E15: ₹14,000–20,000 | F15: Yes (u/s 80C)
B16: Personal Accident | C16: ₹25 Lakh | D16: Any | E16: ₹2,500–4,000 | F16: No

Sheet ✅ 90-Day Plan
B2: ✅ 90-Day Financial Action Plan
B4: ✓ | C4: Action | D4: Why It Matters | E4: Deadline | F4: CA/RIA Needed?
B5: WEEK 1 — SURVIVAL FOUNDATION
B9: MONTH 1 — TAX & INSURANCE
B14: MONTH 2 — RETIREMENT FOUNDATIONS
B19: MONTH 3 — OPTIMISE & REVIEW
